Workbook

Sheet Total Budget
A1: United Crop Care, Gulbarga (KNT)
A2: Yearly Expenses Budget 2026-27
A4: State Head - Mohan Hublikar - SH - Karnataka
A5: State - Karnataka | J5: Date ………..….
A6: Name of Employees | B6: No. of FA | C6: No. of FA's Month | D6: Annual Sales Plan | E6: Annaul Collection Plan | F6: Annual Salary | G6: Annual Travelling | H6: Annual FA Cost | I6: Annual Marketing Budget | J6: Total Cost | K6: Sales : Expense ratio | L6: Collection : Expense ratio
K7: =IFERROR(J7/D7,"-") -> - | L7: =IFERROR(J7/E7,"-") -> -
A8: B. S. Bhandi - Sr. AM - Kalaburagi | B8: =SUM(B9:B12) -> 0 | C8: =SUM(C9:C12) -> 0 | D8: =SUM(D9:D12) -> 0 | E8: =SUM(E9:E12) -> 0 | F8: =SUM(F9:F12) -> 0 | G8: =SUM(G9:G12) -> 0 | H8: =SUM(H9:H12) -> 0 | I8: ='Marketing Budget'!F19 -> 0 | J8: =SUM(F8:I8) -> 0 | K8: =IFERROR(J8/D8,"-") -> - | L8: =IFERROR(J8/E8,"-") -> -
A9: Basavaraj Biradar - ADM - Bidar | I9: ='Marketing Budget'!F35 -> 0 | J9: =SUM(F9:I9) -> 0 | K9: =IFERROR(J9/D9,"-") -> - | L9: =IFERROR(J9/E9,"-") -> -
A10: Basavaraj Devalgudda - SR - Shurpur | I10: ='Marketing Budget'!F51 -> 0 | J10: =SUM(F10:I10) -> 0 | K10: =IFERROR(J10/D10,"-") -> - | L10: =IFERROR(J10/E10,"-") -> -
A11: B S Bhandi, Gulbarga - Direct | I11: ='Marketing Budget'!F67 -> 0 | J11: =SUM(F11:I11) -> 0 | K11: =IFERROR(J11/D11,"-") -> - | L11: =IFERROR(J11/E11,"-") -> -
A12: Mallikarjun Natekar - SR - Humnabad | I12: ='Marketing Budget'!F83 -> 0 | J12: =SUM(F12:I12) -> 0 | K12: =IFERROR(J12/D12,"-") -> - | L12: =IFERROR(J12/E12,"-") -> -
A13: Virupakhappa H - SO - Yadgir & Shahapur | I13: ='Marketing Budget'!F99 -> 0
A14: Vacant | I14: ='Marketing Budget'!F115 -> 0
A16: Gopal Rao Patil - RSM - Bellari | B16: =SUM(B17:B21) -> 0 | C16: =SUM(C17:C21) -> 0 | D16: =SUM(D17:D21) -> 0 | E16: =SUM(E17:E21) -> 0 | F16: =SUM(F17:F21) -> 0 | G16: =SUM(G17:G21) -> 0 | H16: =SUM(H17:H21) -> 0 | I16: ='Marketing Budget'!F132 -> 240000 | J16: =SUM(F16:I16) -> 240000 | K16: =IFERROR(J16/D16,"-") -> - | L16: =IFERROR(J16/E16,"-") -> -
A17: Avinash K N - SSO - Raichur | I17: ='Marketing Budget'!F148 -> 40000 | J17: =SUM(F17:I17) -> 40000 | K17: =IFERROR(J17/D17,"-") -> - | L17: =IFERROR(J17/E17,"-") -> -
A18: K Basavaraj - SO - Talur | I18: ='Marketing Budget'!F164 -> 40000 | J18: =SUM(F18:I18) -> 40000 | K18: =IFERROR(J18/D18,"-") -> - | L18: =IFERROR(J18/E18,"-") -> -
A19: K Kote Lingana Gowda - SO - Ballari | I19: ='Marketing Budget'!F180 -> 40000 | J19: =SUM(F19:I19) -> 40000 | K19: =IFERROR(J19/D19,"-") -> - | L19: =IFERROR(J19/E19,"-") -> -
A20: Vacant - Koppal | I20: ='Marketing Budget'!F196 -> 40000 | J20: =SUM(F20:I20) -> 40000 | K20: =IFERROR(J20/D20,"-") -> - | L20: =IFERROR(J20/E20,"-") -> -
A21: Vacant - Lingasugur | I21: ='Marketing Budget'!F212 -> 0 | J21: =SUM(F21:I21) -> 0 | K21: =IFERROR(J21/D21,"-") -> - | L21: =IFERROR(J21/E21,"-") -> -
A22: Vacant - Maski | I22: ='Marketing Budget'!F228 -> 0
A23: Vacant - Sindhanur | I23: ='Marketing Budget'!F244 -> 0
A24: Vacant - Sirvar | I24: ='Marketing Budget'!F260 -> 0
A25: Vacant - Yemignoor | I25: ='Marketing Budget'!F276 -> 0
A26: Vacant - Vacant | I26: ='Marketing Budget'!F292 -> 0
A28: Siddhigouda S N - SO - Mandya | B28: 0 | C28: 0 | D28: 0 | E28: 0 | F28: 0 | G28: 0 | H28: 0 | I28: ='Marketing Budget'!F308 -> 0 | J28: =SUM(F28:I28) -> 0 | K28: =IFERROR(J28/D28,"-") -> - | L28: =IFERROR(J28/E28,"-") -> -
A30: Somu E - AASM - Chikkaballapur | B30: 2 | C30: 12 | D30: 5000000 | E30: 5000000 | F30: 700000 | G30: 350000 | H30: 220000 | I30: ='Marketing Budget'!F324 -> 80000 | J30: =SUM(F30:I30) -> 1350000 | K30: =IFERROR(J30/D30,"-") -> 0.27 | L30: =IFERROR(J30/E30,"-") -> 0.27
A32: Somu E - AASM - Kadur (Chikamagalore) | B32: =SUM(B33:B35) -> 15 | C32: =SUM(C33:C35) -> 36 | D32: =SUM(D33:D35) -> 1500000 | E32: =SUM(E33:E35) -> 1500000 | F32: =SUM(F33:F35) -> 962000 | G32: =SUM(G33:G35) -> 420000 | H32: =SUM(H33:H35) -> 300000 | I32: ='Marketing Budget'!F340 -> 0 | J32: =SUM(F32:I32) -> 1682000 | K32: =IFERROR(J32/D32,"-") -> 1.1213333 | L32: =IFERROR(J32/E32,"-") -> 1.1213333
A33: Kembegowda - SO - Tumakur | B33: 5 | C33: 12 | D33: 500000 | E33: 500000 | F33: 312000 | G33: 140000 | H33: 100000 | I33: ='Marketing Budget'!F356 -> 0 | J33: =SUM(F33:I33) -> 552000 | K33: =IFERROR(J33/D33,"-") -> 1.104 | L33: =IFERROR(J33/E33,"-") -> 1.104
A34: Kiran C - SR - Kolar | B34: 5 | C34: 12 | D34: 500000 | E34: 500000 | F34: 300000 | G34: 140000 | H34: 100000 | I34: ='Marketing Budget'!F372 -> 0 | J34: =SUM(F34:I34) -> 540000 | K34: =IFERROR(J34/D34,"-") -> 1.08 | L34: =IFERROR(J34/E34,"-") -> 1.08
A35: Mallikarjunapp M - SR - Hassan | B35: 5 | C35: 12 | D35: 500000 | E35: 500000 | F35: 350000 | G35: 140000 | H35: 100000 | I35: ='Marketing Budget'!F388 -> 0 | J35: =SUM(F35:I35) -> 590000 | K35: =IFERROR(J35/D35,"-") -> 1.18 | L35: =IFERROR(J35/E35,"-") -> 1.18
A36: Vacant | I36: ='Marketing Budget'!F404 -> 0 | J36: =SUM(F36:I36) -> 0 | K36: =IFERROR(J36/D36,"-") -> - | L36: =IFERROR(J36/E36,"-") -> -
A38: Vacant - Vacant | B38: =SUM(B39:B41) -> 0 | C38: =SUM(C39:C41) -> 0 | D38: =SUM(D39:D41) -> 0 | E38: =SUM(E39:E41) -> 0 | F38: =SUM(F39:F41) -> 0 | G38: =SUM(G39:G41) -> 0 | H38: =SUM(H39:H41) -> 0 | I38: ='Marketing Budget'!F421 -> 0 | J38: =SUM(F38:I38) -> 0 | K38: =IFERROR(J38/D38,"-") -> - | L38: =IFERROR(J38/E38,"-") -> -
A39: Vacant - 1 | I39: ='Marketing Budget'!F437 -> 0 | J39: =SUM(F39:I39) -> 0 | K39: =IFERROR(J39/D39,"-") -> - | L39: =IFERROR(J39/E39,"-") -> -
A40: Vacant - 2 | I40: ='Marketing Budget'!F453 -> 0 | J40: =SUM(F40:I40) -> 0 | K40: =IFERROR(J40/D40,"-") -> - | L40: =IFERROR(J40/E40,"-") -> -
A41: Vacant - 3 | I41: ='Marketing Budget'!F469 -> 0 | J41: =SUM(F41:I41) -> 0 | K41: =IFERROR(J41/D41,"-") -> - | L41: =IFERROR(J41/E41,"-") -> -
K42: =IFERROR(J42/D42,"-") -> - | L42: =IFERROR(J42/E42,"-") -> -
A43: Mohan Hublikar - SH - Karnataka - Total : | B43: =B38+B32+B30+B28+B16+B8 -> 17 | C43: =C38+C32+C30+C28+C16+C8 -> 48 | D43: =D38+D32+D30+D28+D16+D8 -> 6500000 | E43: =E38+E32+E30+E28+E16+E8 -> 6500000 | F43: =F38+F32+F30+F28+F16+F8 -> 1662000 | G43: =G38+G32+G30+G28+G16+G8 -> 770000 | H43: =H38+H32+H30+H28+H16+H8 -> 520000 | I43: =I38+I32+I30+I28+I16+I8 -> 320000 | J43: =J38+J32+J30+J28+J16+J8 -> 3272000 | K43: =IFERROR(J43/D43,"-") -> 0.50338462 | L43: =IFERROR(J43/E43,"-") -> 0.50338462

Sheet Marketing Budget
B1: United Crop Care, Gulbarga (KNT)
A3: Marketing Budget 2026-27
B5: State Head - Mohan Hublikar - SH - Karnataka
A6: B. S. Bhandi - Sr. AM - Kalaburagi
A7: Type of Marketing Activity | B7: Area for Activity | C7: Crop Targeted | D7: Nos | E7: Rate | F7: Amount
A8: Jeep Campaigning | B8: =B24+B40+B56+B104+B72+B88 -> 0 | C8: =C24+C40+C56+C104+C72+C88 -> 0 | D8: =D24+D40+D56+D104+D72+D88 -> 0 | F8: =D8*E8 -> 0
A9: Litreature | B9: =B25+B41+B57+B105+B73+B89 -> 0 | C9: =C25+C41+C57+C105+C73+C89 -> 0 | D9: =D25+D41+D57+D105+D73+D89 -> 0 | F9: =D9*E9 -> 0
A10: Poster | B10: =B26+B42+B58+B106+B74+B90 -> 0 | C10: =C26+C42+C58+C106+C74+C90 -> 0 | D10: =D26+D42+D58+D106+D74+D90 -> 0 | F10: =D10*E10 -> 0
A11: Dealer Meeting | B11: =B27+B43+B59+B107+B75+B91 -> 0 | C11: =C27+C43+C59+C107+C75+C91 -> 0 | D11: =D27+D43+D59+D107+D75+D91 -> 0 | F11: =D11*E11 -> 0
A12: Farmer Meeting | B12: =B28+B44+B60+B108+B76+B92 -> 0 | C12: =C28+C44+C60+C108+C76+C92 -> 0 | D12: =D28+D44+D60+D108+D76+D92 -> 0 | F12: =D12*E12 -> 0
A13: Crop Shows | B13: =B29+B45+B61+B109+B77+B93 -> 0 | C13: =C29+C45+C61+C109+C77+C93 -> 0 | D13: =D29+D45+D61+D109+D77+D93 -> 0 | F13: =D13*E13 -> 0
A14: Dealer Gifts | B14: =B30+B46+B62+B110+B78+B94 -> 0 | C14: =C30+C46+C62+C110+C78+C94 -> 0 | D14: =D30+D46+D62+D110+D78+D94 -> 0 | F14: =D14*E14 -> 0
A15: Others | B15: =B31+B47+B63+B111+B79+B95 -> 0 | C15: =C31+C47+C63+C111+C79+C95 -> 0 | D15: =D31+D47+D63+D111+D79+D95 -> 0 | F15: =D15*E15 -> 0
A16: Others | B16: =B32+B48+B64+B112+B80+B96 -> 0 | C16: =C32+C48+C64+C112+C80+C96 -> 0 | D16: =D32+D48+D64+D112+D80+D96 -> 0 | F16: =D16*E16 -> 0
A17: Banner | B17: =B33+B49+B65+B113+B81+B97 -> 0 | C17: =C33+C49+C65+C113+C81+C97 -> 0 | D17: =D33+D49+D65+D113+D81+D97 -> 0 | F17: =D17*E17 -> 0
A19: Total : | F19: =SUM(F8:F18) -> 0
A22: Basavaraj Biradar - ADM - Bidar
A23: Type of Marketing Activity | B23: Area for Activity | C23: Crop Targeted | D23: Nos | E23: Rate | F23: Amount
A24: Jeep Campaigning | F24: =D24*E24 -> 0
A25: Litreature | F25: =D25*E25 -> 0
A26: Poster | F26: =D26*E26 -> 0
A27: Dealer Meeting | F27: =D27*E27 -> 0
A28: Farmer Meeting | F28: =D28*E28 -> 0
A29: Crop Shows | F29: =D29*E29 -> 0
A30: Dealer Gifts | F30: =D30*E30 -> 0
A31: Others | F31: =D31*E31 -> 0
A32: Others | F32: =D32*E32 -> 0
A33: Banner | F33: =D33*E33 -> 0
A35: Total : | F35: =SUM(F24:F34) -> 0
A38: Basavaraj Devalgudda - SR - Shurpur
A39: Type of Marketing Activity | B39: Area for Activity | C39: Crop Targeted | D39: Nos | E39: Rate | F39: Amount
A40: Jeep Campaigning | F40: =D40*E40 -> 0
A41: Litreature | F41: =D41*E41 -> 0
A42: Poster | F42: =D42*E42 -> 0
A43: Dealer Meeting | F43: =D43*E43 -> 0
A44: Farmer Meeting | F44: =D44*E44 -> 0
A45: Crop Shows | F45: =D45*E45 -> 0
A46: Dealer Gifts | F46: =D46*E46 -> 0
A47: Others | F47: =D47*E47 -> 0
A48: Others | F48: =D48*E48 -> 0
...
